Workbook

Sheet Hoje
A1: O DIA · o que a oficina tem para fazer e o que já fechou | K1: motor — não apague | L1: =TODAY() -> 46274 | M1: Estas quatro células movem a planilha: a data de hoje, a hora, e o tamanho das duas listas abaixo. Não apague nem mova.
K2: agora | L2: =NOW()-TODAY() -> 0.61104666
A3: DATA | C3: =TODAY() -> 46274 | D3: =IF($C$3="","",TEXT($C$3,"[$-416]dddd")) -> quarta-feira | E3: =IF($C$3="","","semana "&(INT(($C$3-(DATE(Semana!$J$3,1,4)-WEEKDAY(DATE(Semana!$J$3,1,4),3)))/7)+1)) -> semana 37 | F3: ← troque a data para ver outro dia | K3: no dia | L3: =SUM(Programação!$AH$5:$AH$1004) -> 35
K4: atrasadas | L4: =SUM(Programação!$AI$5:$AI$1004) -> 1
A5: PARA FECHAR HOJE | C5: FECHARAM | D5: ADERÊNCIA DO DIA | F5: EM EXECUÇÃO | H5: ATRASADAS | K5: na carteira | L5: =SUMPRODUCT(--(Programação!$AO$5:$AO$1004<>"")) -> 120
A6: =COUNTIFS(Programação!$P$5:$P$1004,$C$3,Programação!$R$5:$R$1004,"<>Cancelada",Programação!$V$5:$V$1004,"Interna") -> 10 | C6: =SUMIFS(Programação!$AB$5:$AB$1004,Programação!$P$5:$P$1004,$C$3,Programação!$V$5:$V$1004,"Interna",Programação!$R$5:$R$1004,"<>Cancelada") -> 9 | D6: =IF($A$6=0,"",$C$6/$A$6) -> 0.9 | F6: =COUNTIFS(Programação!$O$5:$O$1004,"<="&$C$3,Programação!$P$5:$P$1004,">="&$C$3,Programação!$AB$5:$AB$1004,0,Programação!$R$5:$R$1004,"<>Cancelada",Programação!$V$5:$V$1004,"Interna") -> 15 | H6: =COUNTIFS(Programação!$P$5:$P$1004,"<"&$C$3,Programação!$AB$5:$AB$1004,0,Programação!$R$5:$R$1004,"<>Cancelada",Programação!$V$5:$V$1004,"Interna") -> 1
J7: DAR BAIXA
A8: O DIA | D8: ="a janela de execução contém esta data · CONCLUÍDAS NESTA DATA: "&COUNTIFS(Programação!$Q$5:$Q$1004,$C$3,Programação!$R$5:$R$1004,"<>Cancelada",Programação!$V$5:$V$1004,"Interna") -> a janela de execução contém esta data · CONCLUÍDAS NESTA DATA: 7 | J8: escreva a LINHA que a lista mostra e a data — a atividade fecha na Programação
A9: Frota | B9: Serviço | C9: Atividade | D9: Quem faz | E9: Início | F9: Fim | G9: Situação | H9: Concluída em | I9: Linha | J9: Linha | K9: Concluída em | L9: o que você está fechando
A10: =IF($L$3<1,"",INDEX(Programação!$D$5:$D$1004,MATCH(1,Programação!$AE$5:$AE$1004,0))) -> F-815 | B10: =IF($L$3<1,"",INDEX(Programação!$E$5:$E$1004,MATCH(1,Programação!$AE$5:$AE$1004,0))) -> Baixa de pendências backlog | C10: =IF($L$3<1,"",INDEX(Programação!$F$5:$F$1004,MATCH(1,Programação!$AE$5:$AE$1004,0))) -> Fixar farol LD | D10: =IF($L$3<1,"",INDEX(Programação!$AG$5:$AG$1004,MATCH(1,Programação!$AE$5:$AE$1004,0))) -> Alexandre | E10: =IF($L$3<1,"",INDEX(Programação!$O$5:$O$1004,MATCH(1,Programação!$AE$5:$AE$1004,0))) -> 46273 | F10: =IF($L$3<1,"",INDEX(Programação!$P$5:$P$1004,MATCH(1,Programação!$AE$5:$AE$1004,0))) -> 46274 | G10: =IF($A10="","",IF($H10<>"","Concluída",IF($F10<$C$3,"Atrasada",IF($F10=$C$3,"Fecha neste dia","Em execução")))) -> Fecha neste dia | H10: =IF($L$3<1,"",IF(INDEX(Programação!$AT$5:$AT$1004,MATCH(1,Programação!$AE$5:$AE$1004,0))="","",INDEX(Programação!$AT$5:$AT$1004,MATCH(1,Programação!$AE$5:$AE$1004,0)))) | I10: =IF($L$3<1,"",MATCH(1,Programação!$AE$5:$AE$1004,0)+4) -> 122 | L10: =IF($J10="","",IFERROR(INDEX(Programação!$D$5:$D$1004,$J10-4)&" · "&INDEX(Programação!$F$5:$F$1004,$J10-4),"⚠ linha não encontrada"))
A11: =IF($L$3<2,"",INDEX(Programação!$D$5:$D$1004,MATCH(2,Programação!$AE$5:$AE$1004,0))) -> F-815 | B11: =IF($L$3<2,"",INDEX(Programação!$E$5:$E$1004,MATCH(2,Programação!$AE$5:$AE$1004,0))) -> Baixa de pendências backlog | C11: =IF($L$3<2,"",INDEX(Programação!$F$5:$F$1004,MATCH(2,Programação!$AE$5:$AE$1004,0))) -> Corrigir e isolar fiação de iluminação do reboque exposta | D11: =IF($L$3<2,"",INDEX(Programação!$AG$5:$AG$1004,MATCH(2,Programação!$AE$5:$AE$1004,0))) -> Alexandre | E11: =IF($L$3<2,"",INDEX(Programação!$O$5:$O$1004,MATCH(2,Programação!$AE$5:$AE$1004,0))) -> 46273 | F11: =IF($L$3<2,"",INDEX(Programação!$P$5:$P$1004,MATCH(2,Programação!$AE$5:$AE$1004,0))) -> 46275 | G11: =IF($A11="","",IF($H11<>"","Concluída",IF($F11<$C$3,"Atrasada",IF($F11=$C$3,"Fecha neste dia","Em execução")))) -> Em execução | H11: =IF($L$3<2,"",IF(INDEX(Programação!$AT$5:$AT$1004,MATCH(2,Programação!$AE$5:$AE$1004,0))="","",INDEX(Programação!$AT$5:$AT$1004,MATCH(2,Programação!$AE$5:$AE$1004,0)))) | I11: =IF($L$3<2,"",MATCH(2,Programação!$AE$5:$AE$1004,0)+4) -> 127 | L11: =IF($J11="","",IFERROR(INDEX(Programação!$D$5:$D$1004,$J11-4)&" · "&INDEX(Programação!$F$5:$F$1004,$J11-4),"⚠ linha não encontrada"))
A12: =IF($L$3<3,"",INDEX(Programação!$D$5:$D$1004,MATCH(3,Programação!$AE$5:$AE$1004,0))) -> F-815 | B12: =IF($L$3<3,"",INDEX(Programação!$E$5:$E$1004,MATCH(3,Programação!$AE$5:$AE$1004,0))) -> Baixa de pendências backlog | C12: =IF($L$3<3,"",INDEX(Programação!$F$5:$F$1004,MATCH(3,Programação!$AE$5:$AE$1004,0))) -> Corrigir iluminação interna das portas LE e LD | D12: =IF($L$3<3,"",INDEX(Programação!$AG$5:$AG$1004,MATCH(3,Programação!$AE$5:$AE$1004,0))) -> Alexandre | E12: =IF($L$3<3,"",INDEX(Programação!$O$5:$O$1004,MATCH(3,Programação!$AE$5:$AE$1004,0))) -> 46273 | F12: =IF($L$3<3,"",INDEX(Programação!$P$5:$P$1004,MATCH(3,Programação!$AE$5:$AE$1004,0))) -> 46275 | G12: =IF($A12="","",IF($H12<>"","Concluída",IF($F12<$C$3,"Atrasada",IF($F12=$C$3,"Fecha neste dia","Em execução")))) -> Em execução | H12: =IF($L$3<3,"",IF(INDEX(Programação!$AT$5:$AT$1004,MATCH(3,Programação!$AE$5:$AE$1004,0))="","",INDEX(Programação!$AT$5:$AT$1004,MATCH(3,Programação!$AE$5:$AE$1004,0)))) | I12: =IF($L$3<3,"",MATCH(3,Programação!$AE$5:$AE$1004,0)+4) -> 128 | L12: =IF($J12="","",IFERROR(INDEX(Programação!$D$5:$D$1004,$J12-4)&" · "&INDEX(Programação!$F$5:$F$1004,$J12-4),"⚠ linha não encontrada"))
A13: =IF($L$3<4,"",INDEX(Programação!$D$5:$D$1004,MATCH(4,Programação!$AE$5:$AE$1004,0))) -> F-815 | B13: =IF($L$3<4,"",INDEX(Programação!$E$5:$E$1004,MATCH(4,Programação!$AE$5:$AE$1004,0))) -> Baixa de pendências backlog | C13: =IF($L$3<4,"",INDEX(Programação!$F$5:$F$1004,MATCH(4,Programação!$AE$5:$AE$1004,0))) -> Trocar parabrisa | D13: =IF($L$3<4,"",INDEX(Programação!$AG$5:$AG$1004,MATCH(4,Programação!$AE$5:$AE$1004,0))) -> Terceirizada | E13: =IF($L$3<4,"",INDEX(Programação!$O$5:$O$1004,MATCH(4,Programação!$AE$5:$AE$1004,0))) -> 46274 | F13: =IF($L$3<4,"",INDEX(Programação!$P$5:$P$1004,MATCH(4,Programação!$AE$5:$AE$1004,0))) -> 46276 | G13: =IF($A13="","",IF($H13<>"","Concluída",IF($F13<$C$3,"Atrasada",IF($F13=$C$3,"Fecha neste dia","Em execução")))) -> Em execução | H13: =IF($L$3<4,"",IF(INDEX(Programação!$AT$5:$AT$1004,MATCH(4,Programação!$AE$5:$AE$1004,0))="","",INDEX(Programação!$AT$5:$AT$1004,MATCH(4,Programação!$AE$5:$AE$1004,0)))) | I13: =IF($L$3<4,"",MATCH(4,Programação!$AE$5:$AE$1004,0)+4) -> 130 | L13: =IF($J13="","",IFERROR(INDEX(Programação!$D$5:$D$1004,$J13-4)&" · "&INDEX(Programação!$F$5:$F$1004,$J13-4),"⚠ linha não encontrada"))
A14: =IF($L$3<5,"",INDEX(Programação!$D$5:$D$1004,MATCH(5,Programação!$AE$5:$AE$1004,0))) -> F-814 | B14: =IF($L$3<5,"",INDEX(Programação!$E$5:$E$1004,MATCH(5,Programação!$AE$5:$AE$1004,0))) -> BAIXA DE PENDENCIAS | C14: =IF($L$3<5,"",INDEX(Programação!$F$5:$F$1004,MATCH(5,Programação!$AE$5:$AE$1004,0))) -> Regular freio terceiro eixo LE | D14: =IF($L$3<5,"",INDEX(Programação!$AG$5:$AG$1004,MATCH(5,Programação!$AE$5:$AE$1004,0))) -> Heliton | E14: =IF($L$3<5,"",INDEX(Programação!$O$5:$O$1004,MATCH(5,Programação!$AE$5:$AE$1004,0))) -> 46273 | F14: =IF($L$3<5,"",INDEX(Programação!$P$5:$P$1004,MATCH(5,Programação!$AE$5:$AE$1004,0))) -> 46274 | G14: =IF($A14="","",IF($H14<>"","Concluída",IF($F14<$C$3,"Atrasada",IF($F14=$C$3,"Fecha neste dia","Em execução")))) -> Concluída | H14: =IF($L$3<5,"",IF(INDEX(Programação!$AT$5:$AT$1004,MATCH(5,Programação!$AE$5:$AE$1004,0))="","",INDEX(Programação!$AT$5:$AT$1004,MATCH(5,Programação!$AE$5:$AE$1004,0)))) -> 46269 | I14: =IF($L$3<5,"",MATCH(5,Programação!$AE$5:$AE$1004,0)+4) -> 188 | L14: =IF($J14="","",IFERROR(INDEX(Programação!$D$5:$D$1004,$J14-4)&" · "&INDEX(Programação!$F$5:$F$1004,$J14-4),"⚠ linha não encontrada"))
A15: =IF($L$3<6,"",INDEX(Programação!$D$5:$D$1004,MATCH(6,Programação!$AE$5:$AE$1004,0))) -> F-814 | B15: =IF($L$3<6,"",INDEX(Programação!$E$5:$E$1004,MATCH(6,Programação!$AE$5:$AE$1004,0))) -> BAIXA DE PENDENCIAS | C15: =IF($L$3<6,"",INDEX(Programação!$F$5:$F$1004,MATCH(6,Programação!$AE$5:$AE$1004,0))) -> Lubrificar travas da cabine com dificuldade de liberar a mesma para bascular | D15: =IF($L$3<6,"",INDEX(Programação!$AG$5:$AG$1004,MATCH(6,Programação!$AE$5:$AE$1004,0))) -> Júnior · Heliton | E15: =IF($L$3<6,"",INDEX(Programação!$O$5:$O$1004,MATCH(6,Programação!$AE$5:$AE$1004,0))) -> 46273 | F15: =IF($L$3<6,"",INDEX(Programação!$P$5:$P$1004,MATCH(6,Programação!$AE$5:$AE$1004,0))) -> 46274 | G15: =IF($A15="","",IF($H15<>"","Concluída",IF($F15<$C$3,"Atrasada",IF($F15=$C$3,"Fecha neste dia","Em execução")))) -> Concluída | H15: =IF($L$3<6,"",IF(INDEX(Programação!$AT$5:$AT$1004,MATCH(6,Programação!$AE$5:$AE$1004,0))="","",INDEX(Programação!$AT$5:$AT$1004,MATCH(6,Programação!$AE$5:$AE$1004,0)))) -> 46269 | I15: =IF($L$3<6,"",MATCH(6,Programação!$AE$5:$AE$1004,0)+4) -> 191 | L15: =IF($J15="","",IFERROR(INDEX(Programação!$D$5:$D$1004,$J15-4)&" · "&INDEX(Programação!$F$5:$F$1004,$J15-4),"⚠ linha não encontrada"))
A16: =IF($L$3<7,"",INDEX(Programação!$D$5:$D$1004,MATCH(7,Programação!$AE$5:$AE$1004,0))) -> F-815 | B16: =IF($L$3<7,"",INDEX(Programação!$E$5:$E$1004,MATCH(7,Programação!$AE$5:$AE$1004,0))) -> Programação 08/09 | C16: =IF($L$3<7,"",INDEX(Programação!$F$5:$F$1004,MATCH(7,Programação!$AE$5:$AE$1004,0))) -> Montar caixa de direção | D16: =IF($L$3<7,"",INDEX(Programação!$AG$5:$AG$1004,MATCH(7,Programação!$AE$5:$AE$1004,0))) -> Heliton · Adilton | E16: =IF($L$3<7,"",INDEX(Programação!$O$5:$O$1004,MATCH(7,Programação!$AE$5:$AE$1004,0))) -> 46273 | F16: =IF($L$3<7,"",INDEX(Programação!$P$5:$P$1004,MATCH(7,Programação!$AE$5:$AE$1004,0))) -> 46276 | G16: =IF($A16="","",IF($H16<>"","Concluída",IF($F16<$C$3,"Atrasada",IF($F16=$C$3,"Fecha neste dia","Em execução")))) -> Concluída | H16: =IF($L$3<7,"",IF(INDEX(Programação!$AT$5:$AT$1004,MATCH(7,Programação!$AE$5:$AE$1004,0))="","",INDEX(Programação!$AT$5:$AT$1004,MATCH(7,Programação!$AE$5:$AE$1004,0)))) -> 46273 | I16: =IF($L$3<7,"",MATCH(7,Programação!$AE$5:$AE$1004,0)+4) -> 284 | L16: =IF($J16="","",IFERROR(INDEX(Programação!$D$5:$D$1004,$J16-4)&" · "&INDEX(Programação!$F$5:$F$1004,$J16-4),"⚠ linha não encontrada"))
A17: =IF($L$3<8,"",INDEX(Programação!$D$5:$D$1004,MATCH(8,Programação!$AE$5:$AE$1004,0))) -> F-331 | B17: =IF($L$3<8,"",INDEX(Programação!$E$5:$E$1004,MATCH(8,Programação!$AE$5:$AE$1004,0))) -> Programação 08/09 | C17: =IF($L$3<8,"",INDEX(Programação!$F$5:$F$1004,MATCH(8,Programação!$AE$5:$AE$1004,0))) -> Montar limpador de parabrisa | D17: =IF($L$3<8,"",INDEX(Programação!$AG$5:$AG$1004,MATCH(8,Programação!$AE$5:$AE$1004,0))) -> Gabriel | E17: =IF($L$3<8,"",INDEX(Programação!$O$5:$O$1004,MATCH(8,Programação!$AE$5:$AE$1004,0))) -> 46273 | F17: =IF($L$3<8,"",INDEX(Programação!$P$5:$P$1004,MATCH(8,Programação!$AE$5:$AE$1004,0))) -> 46274 | G17: =IF($A17="","",IF($H17<>"","Concluída",IF($F17<$C$3,"Atrasada",IF($F17=$C$3,"Fecha neste dia","Em execução")))) -> Concluída | H17: =IF($L$3<8,"",IF(INDEX(Programação!$AT$5:$AT$1004,MATCH(8,Programação!$AE$5:$AE$1004,0))="","",INDEX(Programação!$AT$5:$AT$1004,MATCH(8,Programação!$AE$5:$AE$1004,0)))) -> 46273 | I17: =IF($L$3<8,"",MATCH(8,Programação!$AE$5:$AE$1004,0)+4) -> 286 | L17: =IF($J17="","",IFERROR(INDEX(Programação!$D$5:$D$1004,$J17-4)&" · "&INDEX(Programação!$F$5:$F$1004,$J17-4),"⚠ linha não encontrada"))
A18: =IF($L$3<9,"",INDEX(Programação!$D$5:$D$1004,MATCH(9,Programação!$AE$5:$AE$1004,0))) -> F-331 | B18: =IF($L$3<9,"",INDEX(Programação!$E$5:$E$1004,MATCH(9,Programação!$AE$5:$AE$1004,0))) -> Programação 08/09 | C18: =IF($L$3<9,"",INDEX(Programação!$F$5:$F$1004,MATCH(9,Programação!$AE$5:$AE$1004,0))) -> Trocar mangueiras | D18: =IF($L$3<9,"",INDEX(Programação!$AG$5:$AG$1004,MATCH(9,Programação!$AE$5:$AE$1004,0))) -> Gabriel | E18: =IF($L$3<9,"",INDEX(Programação!$O$5:$O$1004,MATCH(9,Programação!$AE$5:$AE$1004,0))) -> 46273 | F18: =IF($L$3<9,"",INDEX(Programação!$P$5:$P$1004,MATCH(9,Programação!$AE$5:$AE$1004,0))) -> 46275 | G18: =IF($A18="","",IF($H18<>"","Concluída",IF($F18<$C$3,"Atrasada",IF($F18=$C$3,"Fecha neste dia","Em execução")))) -> Concluída | H18: =IF($L$3<9,"",IF(INDEX(Programação!$AT$5:$AT$1004,MATCH(9,Programação!$AE$5:$AE$1004,0))="","",INDEX(Programação!$AT$5:$AT$1004,MATCH(9,Programação!$AE$5:$AE$1004,0)))) -> 46273 | I18: =IF($L$3<9,"",MATCH(9,Programação!$AE$5:$AE$1004,0)+4) -> 287 | L18: =IF($J18="","",IFERROR(INDEX(Programação!$D$5:$D$1004,$J18-4)&" · "&INDEX(Programação!$F$5:$F$1004,$J18-4),"⚠ linha não encontrada"))
A19: =IF($L$3<10,"",INDEX(Programação!$D$5:$D$1004,MATCH(10,Programação!$AE$5:$AE$1004,0))) -> F-1064 | B19: =IF($L$3<10,"",INDEX(Programação!$E$5:$E$1004,MATCH(10,Programação!$AE$5:$AE$1004,0))) -> Programação 08/09 | C19: =IF($L$3<10,"",INDEX(Programação!$F$5:$F$1004,MATCH(10,Programação!$AE$5:$AE$1004,0))) -> Lubrificar quinta roda | D19: =IF($L$3<10,"",INDEX(Programação!$AG$5:$AG$1004,MATCH(10,Programação!$AE$5:$AE$1004,0))) -> Gabriel · Júnior | E19: =IF($L$3<10,"",INDEX(Programação!$O$5:$O$1004,MATCH(10,Programação!$AE$5:$AE$1004,0))) -> 46273 | F19: =IF($L$3<10,"",INDEX(Programação!$P$5:$P$1004,MATCH(10,Programação!$AE$5:$AE$1004,0))) -> 46274 | G19: =IF($A19="","",IF($H19<>"","Concluída",IF($F19<$C$3,"Atrasada",IF($F19=$C$3,"Fecha neste dia","Em execução")))) -> Concluída | H19: =IF($L$3<10,"",IF(INDEX(Programação!$AT$5:$AT$1004,MATCH(10,Programação!$AE$5:$AE$1004,0))="","",INDEX(Programação!$AT$5:$AT$1004,MATCH(10,Programação!$AE$5:$AE$1004,0)))) -> 46273 | I19: =IF($L$3<10,"",MATCH(10,Programação!$AE$5:$AE$1004,0)+4) -> 289 | L19: =IF($J19="","",IFERROR(INDEX(Programação!$D$5:$D$1004,$J19-4)&" · "&INDEX(Programação!$F$5:$F$1004,$J19-4),"⚠ linha não encontrada"))
A20: =IF($L$3<11,"",INDEX(Programação!$D$5:$D$1004,MATCH(11,Programação!$AE$5:$AE$1004,0))) -> F-1064 | B20: =IF($L$3<11,"",INDEX(Programação!$E$5:$E$1004,MATCH(11,Programação!$AE$5:$AE$1004,0))) -> Programação 08/09 | C20: =IF($L$3<11,"",INDEX(Programação!$F$5:$F$1004,MATCH(11,Programação!$AE$5:$AE$1004,0))) -> Instalar tag da frota | D20: =IF($L$3<11,"",INDEX(Programação!$AG$5:$AG$1004,MATCH(11,Programação!$AE$5:$AE$1004,0))) -> Gabriel · Júnior | E20: =IF($L$3<11,"",INDEX(Programação!$O$5:$O$1004,MATCH(11,Programação!$AE$5:$AE$1004,0))) -> 46273 | F20: =IF($L$3<11,"",INDEX(Programação!$P$5:$P$1004,MATCH(11,Programação!$AE$5:$AE$1004,0))) -> 46274 | G20: =IF($A20="","",IF($H20<>"","Concluída",IF($F20<$C$3,"Atrasada",IF($F20=$C$3,"Fecha neste dia","Em execução")))) -> Concluída | H20: =IF($L$3<11,"",IF(INDEX(Programação!$AT$5:$AT$1004,MATCH(11,Programação!$AE$5:$AE$1004,0))="","",INDEX(Programação!$AT$5:$AT$1004,MATCH(11,Programação!$AE$5:$AE$1004,0)))) -> 46273 | I20: =IF($L$3<11,"",MATCH(11,Programação!$AE$5:$AE$1004,0)+4) -> 290 | L20: =IF($J20="","",IFERROR(INDEX(Programação!$D$5:$D$1004,$J20-4)&" · "&INDEX(Programação!$F$5:$F$1004,$J20-4),"⚠ linha não encontrada"))
A21: =IF($L$3<12,"",INDEX(Programação!$D$5:$D$1004,MATCH(12,Programação!$AE$5:$AE$1004,0))) -> F-1064 | B21: =IF($L$3<12,"",INDEX(Programação!$E$5:$E$1004,MATCH(12,Programação!$AE$5:$AE$1004,0))) -> Programação 08/09 | C21: =IF($L$3<12,"",INDEX(Programação!$F$5:$F$1004,MATCH(12,Programação!$AE$5:$AE$1004,0))) -> Instalar indicadores de folga nas porcas de roda | D21: =IF($L$3<12,"",INDEX(Programação!$AG$5:$AG$1004,MATCH(12,Programação!$AE$5:$AE$1004,0))) -> Luiz Paulo | E21: =IF($L$3<12,"",INDEX(Programação!$O$5:$O$1004,MATCH(12,Programação!$AE$5:$AE$1004,0))) -> 46274 | F21: =IF($L$3<12,"",INDEX(Programação!$P$5:$P$1004,MATCH(12,Programação!$AE$5:$AE$1004,0))) -> 46276 | G21: =IF($A21="","",IF($H21<>"","Concluída",IF($F21<$C$3,"Atrasada",IF($F21=$C$3,"Fecha neste dia","Em execução")))) -> Concluída | H21: =IF($L$3<12,"",IF(INDEX(Programação!$AT$5:$AT$1004,MATCH(12,Programação!$AE$5:$AE$1004,0))="","",INDEX(Programação!$AT$5:$AT$1004,MATCH(12,Programação!$AE$5:$AE$1004,0)))) -> 46274 | I21: =IF($L$3<12,"",MATCH(12,Programação!$AE$5:$AE$1004,0)+4) -> 291 | L21: =IF($J21="","",IFERROR(INDEX(Programação!$D$5:$D$1004,$J21-4)&" · "&INDEX(Programação!$F$5:$F$1004,$J21-4),"⚠ linha não encontrada"))
A22: =IF($L$3<13,"",INDEX(Programação!$D$5:$D$1004,MATCH(13,Programação!$AE$5:$AE$1004,0))) -> F-1064 | B22: =IF($L$3<13,"",INDEX(Programação!$E$5:$E$1004,MATCH(13,Programação!$AE$5:$AE$1004,0))) -> Programação 08/09 | C22: =IF($L$3<13,"",INDEX(Programação!$F$5:$F$1004,MATCH(13,Programação!$AE$5:$AE$1004,0))) -> Substituir estepe avariado na banda de rodagem | D22: =IF($L$3<13,"",INDEX(Programação!$AG$5:$AG$1004,MATCH(13,Programação!$AE$5:$AE$1004,0))) -> Gabriel · Júnior | E22: =IF($L$3<13,"",INDEX(Programação!$O$5:$O$1004,MATCH(13,Programação!$AE$5:$AE$1004,0))) -> 46273 | F22: =IF($L$3<13,"",INDEX(Programação!$P$5:$P$1004,MATCH(13,Programação!$AE$5:$AE$1004,0))) -> 46276 | G22: =IF($A22="","",IF($H22<>"","Concluída",IF($F22<$C$3,"Atrasada",IF($F22=$C$3,"Fecha neste dia","Em execução")))) -> Em execução | H22: =IF($L$3<13,"",IF(INDEX(Programação!$AT$5:$AT$1004,MATCH(13,Programação!$AE$5:$AE$1004,0))="","",INDEX(Programação!$AT$5:$AT$1004,MATCH(13,Programação!$AE$5:$AE$1004,0)))) | I22: =IF($L$3<13,"",MATCH(13,Programação!$AE$5:$AE$1004,0)+4) -> 292 | L22: =IF($J22="","",IFERROR(INDEX(Programação!$D$5:$D$1004,$J22-4)&" · "&INDEX(Programação!$F$5:$F$1004,$J22-4),"⚠ linha não encontrada"))
A23: =IF($L$3<14,"",INDEX(Programação!$D$5:$D$1004,MATCH(14,Programação!$AE$5:$AE$1004,0))) -> F-1064 | B23: =IF($L$3<14,"",INDEX(Programação!$E$5:$E$1004,MATCH(14,Programação!$AE$5:$AE$1004,0))) -> Programação 08/09 | C23: =IF($L$3<14,"",INDEX(Programação!$F$5:$F$1004,MATCH(14,Programação!$AE$5:$AE$1004,0))) -> Instalar quebra dedo na trava da tampa do baú LD | D23: =IF($L$3<14,"",INDEX(Programação!$AG$5:$AG$1004,MATCH(14,Programação!$AE$5:$AE$1004,0))) -> Gabriel · Júnior | E23: =IF($L$3<14,"",INDEX(Programação!$O$5:$O$1004,MATCH(14,Programação!$AE$5:$AE$1004,0))) -> 46273 | F23: =IF($L$3<14,"",INDEX(Programação!$P$5:$P$1004,MATCH(14,Programação!$AE$5:$AE$1004,0))) -> 46276 | G23: =IF($A23="","",IF($H23<>"","Concluída",IF($F23<$C$3,"Atrasada",IF($F23=$C$3,"Fecha neste dia","Em execução")))) -> Em execução | H23: =IF($L$3<14,"",IF(INDEX(Programação!$AT$5:$AT$1004,MATCH(14,Programação!$AE$5:$AE$1004,0))="","",INDEX(Programação!$AT$5:$AT$1004,MATCH(14,Programação!$AE$5:$AE$1004,0)))) | I23: =IF($L$3<14,"",MATCH(14,Programação!$AE$5:$AE$1004,0)+4) -> 293 | L23: =IF($J23="","",IFERROR(INDEX(Programação!$D$5:$D$1004,$J23-4)&" · "&INDEX(Programação!$F$5:$F$1004,$J23-4),"⚠ linha não encontrada"))
A24: =IF($L$3<15,"",INDEX(Programação!$D$5:$D$1004,MATCH(15,Programação!$AE$5:$AE$1004,0))) -> F-1065 | B24: =IF($L$3<15,"",INDEX(Programação!$E$5:$E$1004,MATCH(15,Programação!$AE$5:$AE$1004,0))) -> Programação 08/09 | C24: =IF($L$3<15,"",INDEX(Programação!$F$5:$F$1004,MATCH(15,Programação!$AE$5:$AE$1004,0))) -> Instalar sirene de ré | D24: =IF($L$3<15,"",INDEX(Programação!$AG$5:$AG$1004,MATCH(15,Programação!$AE$5:$AE$1004,0))) -> Gabriel · Júnior | E24: =IF($L$3<15,"",INDEX(Programação!$O$5:$O$1004,MATCH(15,Programação!$AE$5:$AE$1004,0))) -> 46273 | F24: =IF($L$3<15,"",INDEX(Programação!$P$5:$P$1004,MATCH(15,Programação!$AE$5:$AE$1004,0))) -> 46274 | G24: =IF($A24="","",IF($H24<>"","Concluída",IF($F24<$C$3,"Atrasada",IF($F24=$C$3,"Fecha neste dia","Em execução")))) -> Concluída | H24: =IF($L$3<15,"",IF(INDEX(Programação!$AT$5:$AT$1004,MATCH(15,Programação!$AE$5:$AE$1004,0))="","",INDEX(Programação!$AT$5:$AT$1004,MATCH(15,Programação!$AE$5:$AE$1004,0)))) -> 46274 | I24: =IF($L$3<15,"",MATCH(15,Programação!$AE$5:$AE$1004,0)+4) -> 294 | L24: =IF($J24="","",IFERROR(INDEX(Programação!$D$5:$D$1004,$J24-4)&" · "&INDEX(Programação!$F$5:$F$1004,$J24-4),"⚠ linha não encontrada"))
A25: =IF($L$3<16,"",INDEX(Programação!$D$5:$D$1004,MATCH(16,Programação!$AE$5:$AE$1004,0))) -> F-1065 | B25: =IF($L$3<16,"",INDEX(Programação!$E$5:$E$1004,MATCH(16,Programação!$AE$5:$AE$1004,0))) -> Programação 08/09 | C25: =IF($L$3<16,"",INDEX(Programação!$F$5:$F$1004,MATCH(16,Programação!$AE$5:$AE$1004,0))) -> Instalar tag da frota | D25: =IF($L$3<16,"",INDEX(Programação!$AG$5:$AG$1004,MATCH(16,Programação!$AE$5:$AE$1004,0))) -> Gabriel · Júnior | E25: =IF($L$3<16,"",INDEX(Programação!$O$5:$O$1004,MATCH(16,Programação!$AE$5:$AE$1004,0))) -> 46273 | F25: =IF($L$3<16,"",INDEX(Programação!$P$5:$P$1004,MATCH(16,Programação!$AE$5:$AE$1004,0))) -> 46275 | G25: =IF($A25="","",IF($H25<>"","Concluída",IF($F25<$C$3,"Atrasada",IF($F25=$C$3,"Fecha neste dia","Em execução")))) -> Concluída | H25: =IF($L$3<16,"",IF(INDEX(Programação!$AT$5:$AT$1004,MATCH(16,Programação!$AE$5:$AE$1004,0))="","",INDEX(Programação!$AT$5:$AT$1004,MATCH(16,Programação!$AE$5:$AE$1004,0)))) -> 46273 | I25: =IF($L$3<16,"",MATCH(16,Programação!$AE$5:$AE$1004,0)+4) -> 295 | L25: =IF($J25="","",IFERROR(INDEX(Programação!$D$5:$D$1004,$J25-4)&" · "&INDEX(Programação!$F$5:$F$1004,$J25-4),"⚠ linha não encontrada"))
A26: =IF($L$3<17,"",INDEX(Programação!$D$5:$D$1004,MATCH(17,Programação!$AE$5:$AE$1004,0))) -> F-1065 | B26: =IF($L$3<17,"",INDEX(Programação!$E$5:$E$1004,MATCH(17,Programação!$AE$5:$AE$1004,0))) -> Programação 08/09 | C26: =IF($L$3<17,"",INDEX(Programação!$F$5:$F$1004,MATCH(17,Programação!$AE$5:$AE$1004,0))) -> Instalar indicadores de folga nas porcas de roda | D26: =IF($L$3<17,"",INDEX(Programação!$AG$5:$AG$1004,MATCH(17,Programação!$AE$5:$AE$1004,0))) -> Luiz Paulo | E26: =IF($L$3<17,"",INDEX(Programação!$O$5:$O$1004,MATCH(17,Programação!$AE$5:$AE$1004,0))) -> 46274 | F26: =IF($L$3<17,"",INDEX(Programação!$P$5:$P$1004,MATCH(17,Programação!$AE$5:$AE$1004,0))) -> 46277 | G26: =IF($A26="","",IF($H26<>"","Concluída",IF($F26<$C$3,"Atrasada",IF($F26=$C$3,"Fecha neste dia","Em execução")))) -> Concluída | H26: =IF($L$3<17,"",IF(INDEX(Programação!$AT$5:$AT$1004,MATCH(17,Programação!$AE$5:$AE$1004,0))="","",INDEX(Programação!$AT$5:$AT$1004,MATCH(17,Programação!$AE$5:$AE$1004,0)))) -> 46274 | I26: =IF($L$3<17,"",MATCH(17,Programação!$AE$5:$AE$1004,0)+4) -> 296 | L26: =IF($J26="","",IFERROR(INDEX(Programação!$D$5:$D$1004,$J26-4)&" · "&INDEX(Programação!$F$5:$F$1004,$J26-4),"⚠ linha não encontrada"))
A27: =IF($L$3<18,"",INDEX(Programação!$D$5:$D$1004,MATCH(18,Programação!$AE$5:$AE$1004,0))) -> F-1063 | B27: =IF($L$3<18,"",INDEX(Programação!$E$5:$E$1004,MATCH(18,Programação!$AE$5:$AE$1004,0))) -> Programação 08/09 | C27: =IF($L$3<18,"",INDEX(Programação!$F$5:$F$1004,MATCH(18,Programação!$AE$5:$AE$1004,0))) -> Fixar para-lama primeiro eixo LD | D27: =IF($L$3<18,"",INDEX(Programação!$AG$5:$AG$1004,MATCH(18,Programação!$AE$5:$AE$1004,0))) -> Gabriel · Júnior | E27: =IF($L$3<18,"",INDEX(Programação!$O$5:$O$1004,MATCH(18,Programação!$AE$5:$AE$1004,0))) -> 46273 | F27: =IF($L$3<18,"",INDEX(Programação!$P$5:$P$1004,MATCH(18,Programação!$AE$5:$AE$1004,0))) -> 46274 | G27: =IF($A27="","",IF($H27<>"","Concluída",IF($F27<$C$3,"Atrasada",IF($F27=$C$3,"Fecha neste dia","Em execução")))) -> Concluída | H27: =IF($L$3<18,"",IF(INDEX(Programação!$AT$5:$AT$1004,MATCH(18,Programação!$AE$5:$AE$1004,0))="","",INDEX(Programação!$AT$5:$AT$1004,MATCH(18,Programação!$AE$5:$AE$1004,0)))) -> 46273 | I27: =IF($L$3<18,"",MATCH(18,Programação!$AE$5:$AE$1004,0)+4) -> 297 | L27: =IF($J27="","",IFERROR(INDEX(Programação!$D$5:$D$1004,$J27-4)&" · "&INDEX(Programação!$F$5:$F$1004,$J27-4),"⚠ linha não encontrada"))
A28: =IF($L$3<19,"",INDEX(Programação!$D$5:$D$1004,MATCH(19,Programação!$AE$5:$AE$1004,0))) -> F-1063 | B28: =IF($L$3<19,"",INDEX(Programação!$E$5:$E$1004,MATCH(19,Programação!$AE$5:$AE$1004,0))) -> Programação 08/09 | C28: =IF($L$3<19,"",INDEX(Programação!$F$5:$F$1004,MATCH(19,Programação!$AE$5:$AE$1004,0))) -> Fixar grade de proteção do ciclista traseira LD | D28: =IF($L$3<19,"",INDEX(Programação!$AG$5:$AG$1004,MATCH(19,Programação!$AE$5:$AE$1004,0))) -> Gabriel · Júnior | E28: =IF($L$3<19,"",INDEX(Programação!$O$5:$O$1004,MATCH(19,Programação!$AE$5:$AE$1004,0))) -> 46273 | F28: =IF($L$3<19,"",INDEX(Programação!$P$5:$P$1004,MATCH(19,Programação!$AE$5:$AE$1004,0))) -> 46276 | G28: =IF($A28="","",IF($H28<>"","Concluída",IF($F28<$C$3,"Atrasada",IF($F28=$C$3,"Fecha neste dia","Em execução")))) -> Concluída | H28: =IF($L$3<19,"",IF(INDEX(Programação!$AT$5:$AT$1004,MATCH(19,Programação!$AE$5:$AE$1004,0))="","",INDEX(Programação!$AT$5:$AT$1004,MATCH(19,Programação!$AE$5:$AE$1004,0)))) -> 46273 | I28: =IF($L$3<19,"",MATCH(19,Programação!$AE$5:$AE$1004,0)+4) -> 298 | L28: =IF($J28="","",IFERROR(INDEX(Programação!$D$5:$D$1004,$J28-4)&" · "&INDEX(Programação!$F$5:$F$1004,$J28-4),"⚠ linha não encontrada"))
A29: =IF($L$3<20,"",INDEX(Programação!$D$5:$D$1004,MATCH(20,Programação!$AE$5:$AE$1004,0))) -> F-1062 | B29: =IF($L$3<20,"",INDEX(Programação!$E$5:$E$1004,MATCH(20,Programação!$AE$5:$AE$1004,0))) -> Programação 08/09 | C29: =IF($L$3<20,"",INDEX(Programação!$F$5:$F$1004,MATCH(20,Programação!$AE$5:$AE$1004,0))) -> Fixar para-lama terceiro eixo LE | D29: =IF($L$3<20,"",INDEX(Programação!$AG$5:$AG$1004,MATCH(20,Programação!$AE$5:$AE$1004,0))) -> Gabriel · Júnior | E29: =IF($L$3<20,"",INDEX(Programação!$O$5:$O$1004,MATCH(20,Programação!$AE$5:$AE$1004,0))) -> 46273 | F29: =IF($L$3<20,"",INDEX(Programação!$P$5:$P$1004,MATCH(20,Programação!$AE$5:$AE$1004,0))) -> 46274 | G29: =IF($A29="","",IF($H29<>"","Concluída",IF($F29<$C$3,"Atrasada",IF($F29=$C$3,"Fecha neste dia","Em execução")))) -> Concluída | H29: =IF($L$3<20,"",IF(INDEX(Programação!$AT$5:$AT$1004,MATCH(20,Programação!$AE$5:$AE$1004,0))="","",INDEX(Programação!$AT$5:$AT$1004,MATCH(20,Programação!$AE$5:$AE$1004,0)))) -> 46273 | I29: =IF($L$3<20,"",MATCH(20,Programação!$AE$5:$AE$1004,0)+4) -> 300 | L29: =IF($J29="","",IFERROR(INDEX(Programação!$D$5:$D$1004,$J29-4)&" · "&INDEX(Programação!$F$5:$F$1004,$J29-4),"⚠ linha não encontrada"))
A30: =IF($L$3<21,"",INDEX(Programação!$D$5:$D$1004,MATCH(21,Programação!$AE$5:$AE$1004,0))) -> F-1062 | B30: =IF($L$3<21,"",INDEX(Programação!$E$5:$E$1004,MATCH(21,Programação!$AE$5:$AE$1004,0))) -> Programação 08/09 | C30: =IF($L$3<21,"",INDEX(Programação!$F$5:$F$1004,MATCH(21,Programação!$AE$5:$AE$1004,0))) -> Regular freios segundo e terceiro eixo | D30: =IF($L$3<21,"",INDEX(Programação!$AG$5:$AG$1004,MATCH(21,Programação!$AE$5:$AE$1004,0))) -> Gabriel · Júnior | E30: =IF($L$3<21,"",INDEX(Programação!$O$5:$O$1004,MATCH(21,Programação!$AE$5:$AE$1004,0))) -> 46273 | F30: =IF($L$3<21,"",INDEX(Programação!$P$5:$P$1004,MATCH(21,Programação!$AE$5:$AE$1004,0))) -> 46274 | G30: =IF($A30="","",IF($H30<>"","Concluída",IF($F30<$C$3,"Atrasada",IF($F30=$C$3,"Fecha neste dia","Em execução")))) -> Concluída | H30: =IF($L$3<21,"",IF(INDEX(Programação!$AT$5:$AT$1004,MATCH(21,Programação!$AE$5:$AE$1004,0))="","",INDEX(Programação!$AT$5:$AT$1004,MATCH(21,Programação!$AE$5:$AE$1004,0)))) -> 46273 | I30: =IF($L$3<21,"",MATCH(21,Programação!$AE$5:$AE$1004,0)+4) -> 301
A31: =IF($L$3<22,"",INDEX(Programação!$D$5:$D$1004,MATCH(22,Programação!$AE$5:$AE$1004,0))) -> F-1062 | B31: =IF($L$3<22,"",INDEX(Programação!$E$5:$E$1004,MATCH(22,Programação!$AE$5:$AE$1004,0))) -> Programação 08/09 | C31: =IF($L$3<22,"",INDEX(Programação!$F$5:$F$1004,MATCH(22,Programação!$AE$5:$AE$1004,0))) -> Repor parafusos das tampas do cubo de roda primeiro e terceiro eixo LE | D31: =IF($L$3<22,"",INDEX(Programação!$AG$5:$AG$1004,MATCH(22,Programação!$AE$5:$AE$1004,0))) -> Gabriel · Júnior | E31: =IF($L$3<22,"",INDEX(Programação!$O$5:$O$1004,MATCH(22,Programação!$AE$5:$AE$1004,0))) -> 46273 | F31: =IF($L$3<22,"",INDEX(Programação!$P$5:$P$1004,MATCH(22,Programação!$AE$5:$AE$1004,0))) -> 46275 | G31: =IF($A31="","",IF($H31<>"","Concluída",IF($F31<$C$3,"Atrasada",IF($F31=$C$3,"Fecha neste dia","Em execução")))) -> Concluída | H31: =IF($L$3<22,"",IF(INDEX(Programação!$AT$5:$AT$1004,MATCH(22,Programação!$AE$5:$AE$1004,0))="","",INDEX(Programação!$AT$5:$AT$1004,MATCH(22,Programação!$AE$5:$AE$1004,0)))) -> 46273 | I31: =IF($L$3<22,"",MATCH(22,Programação!$AE$5:$AE$1004,0)+4) -> 303
A32: =IF($L$3<23,"",INDEX(Programação!$D$5:$D$1004,MATCH(23,Programação!$AE$5:$AE$1004,0))) -> F-580 | B32: =IF($L$3<23,"",INDEX(Programação!$E$5:$E$1004,MATCH(23,Programação!$AE$5:$AE$1004,0))) -> Programação 09/09 | C32: =IF($L$3<23,"",INDEX(Programação!$F$5:$F$1004,MATCH(23,Programação!$AE$5:$AE$1004,0))) -> Retirar módulo | D32: =IF($L$3<23,"",INDEX(Programação!$AG$5:$AG$1004,MATCH(23,Programação!$AE$5:$AE$1004,0))) -> Alexandre | E32: =IF($L$3<23,"",INDEX(Programação!$O$5:$O$1004,MATCH(23,Programação!$AE$5:$AE$1004,0))) -> 46274 | F32: =IF($L$3<23,"",INDEX(Programação!$P$5:$P$1004,MATCH(23,Programação!$AE$5:$AE$1004,0))) -> 46276 | G32: =IF($A32="","",IF($H32<>"","Concluída",IF($F32<$C$3,"Atrasada",IF($F32=$C$3,"Fecha neste dia","Em execução")))) -> Em execução | H32: =IF($L$3<23,"",IF(INDEX(Programação!$AT$5:$AT$1004,MATCH(23,Programação!$AE$5:$AE$1004,0))="","",INDEX(Programação!$AT$5:$AT$1004,MATCH(23,Programação!$AE$5:$AE$1004,0)))) | I32: =IF($L$3<23,"",MATCH(23,Programação!$AE$5:$AE$1004,0)+4) -> 363
A33: =IF($L$3<24,"",INDEX(Programação!$D$5:$D$1004,MATCH(24,Programação!$AE$5:$AE$1004,0))) -> F-938 | B33: =IF($L$3<24,"",INDEX(Programação!$E$5:$E$1004,MATCH(24,Programação!$AE$5:$AE$1004,0))) -> Programação 09/09 | C33: =IF($L$3<24,"",INDEX(Programação!$F$5:$F$1004,MATCH(24,Programação!$AE$5:$AE$1004,0))) -> Trocar baterias | D33: =IF($L$3<24,"",INDEX(Programação!$AG$5:$AG$1004,MATCH(24,Programação!$AE$5:$AE$1004,0))) -> Alexandre · Gabriel | E33: =IF($L$3<24,"",INDEX(Programação!$O$5:$O$1004,MATCH(24,Programação!$AE$5:$AE$1004,0))) -> 46274 | F33: =IF($L$3<24,"",INDEX(Programação!$P$5:$P$1004,MATCH(24,Programação!$AE$5:$AE$1004,0))) -> 46275 | G33: =IF($A33="","",IF($H33<>"","Concluída",IF($F33<$C$3,"Atrasada",IF($F33=$C$3,"Fecha neste dia","Em execução")))) -> Em execução | H33: =IF($L$3<24,"",IF(INDEX(Programação!$AT$5:$AT$1004,MATCH(24,Programação!$AE$5:$AE$1004,0))="","",INDEX(Programação!$AT$5:$AT$1004,MATCH(24,Programação!$AE$5:$AE$1004,0)))) | I33: =IF($L$3<24,"",MATCH(24,Programação!$AE$5:$AE$1004,0)+4) -> 364
A34: =IF($L$3<25,"",INDEX(Programação!$D$5:$D$1004,MATCH(25,Programação!$AE$5:$AE$1004,0))) -> F-815 | B34: =IF($L$3<25,"",INDEX(Programação!$E$5:$E$1004,MATCH(25,Programação!$AE$5:$AE$1004,0))) -> Programação 09/09 | C34: =IF($L$3<25,"",INDEX(Programação!$F$5:$F$1004,MATCH(25,Programação!$AE$5:$AE$1004,0))) -> Montar retrovisor | D34: =IF($L$3<25,"",INDEX(Programação!$AG$5:$AG$1004,MATCH(25,Programação!$AE$5:$AE$1004,0))) -> Heliton | E34: =IF($L$3<25,"",INDEX(Programação!$O$5:$O$1004,MATCH(25,Programação!$AE$5:$AE$1004,0))) -> 46274 | F34: =IF($L$3<25,"",INDEX(Programação!$P$5:$P$1004,MATCH(25,Programação!$AE$5:$AE$1004,0))) -> 46275 | G34: =IF($A34="","",IF($H34<>"","Concluída",IF($F34<$C$3,"Atrasada",IF($F34=$C$3,"Fecha neste dia","Em execução")))) -> Em execução | H34: =IF($L$3<25,"",IF(INDEX(Programação!$AT$5:$AT$1004,MATCH(25,Programação!$AE$5:$AE$1004,0))="","",INDEX(Programação!$AT$5:$AT$1004,MATCH(25,Programação!$AE$5:$AE$1004,0)))) | I34: =IF($L$3<25,"",MATCH(25,Programação!$AE$5:$AE$1004,0)+4) -> 365
A35: =IF($L$3<26,"",INDEX(Programação!$D$5:$D$1004,MATCH(26,Programação!$AE$5:$AE$1004,0))) -> F-426 | B35: =IF($L$3<26,"",INDEX(Programação!$E$5:$E$1004,MATCH(26,Programação!$AE$5:$AE$1004,0))) -> Programação 09/09 | C35: =IF($L$3<26,"",INDEX(Programação!$F$5:$F$1004,MATCH(26,Programação!$AE$5:$AE$1004,0))) -> Corrigir parte elétrica | D35: =IF($L$3<26,"",INDEX(Programação!$AG$5:$AG$1004,MATCH(26,Programação!$AE$5:$AE$1004,0))) -> Alexandre · Gabriel | E35: =IF($L$3<26,"",INDEX(Programação!$O$5:$O$1004,MATCH(26,Programação!$AE$5:$AE$1004,0))) -> 46274 | F35: =IF($L$3<26,"",INDEX(Programação!$P$5:$P$1004,MATCH(26,Programação!$AE$5:$AE$1004,0))) -> 46276 | G35: =IF($A35="","",IF($H35<>"","Concluída",IF($F35<$C$3,"Atrasada",IF($F35=$C$3,"Fecha neste dia","Em execução")))) -> Em execução | H35: =IF($L$3<26,"",IF(INDEX(Programação!$AT$5:$AT$1004,MATCH(26,Programação!$AE$5:$AE$1004,0))="","",INDEX(Programação!$AT$5:$AT$1004,MATCH(26,Programação!$AE$5:$AE$1004,0)))) | I35: =IF($L$3<26,"",MATCH(26,Programação!$AE$5:$AE$1004,0)+4) -> 366
A36: =IF($L$3<27,"",INDEX(Programação!$D$5:$D$1004,MATCH(27,Programação!$AE$5:$AE$1004,0))) -> F-618 | B36: =IF($L$3<27,"",INDEX(Programação!$E$5:$E$1004,MATCH(27,Programação!$AE$5:$AE$1004,0))) -> Programação 09/09 | C36: =IF($L$3<27,"",INDEX(Programação!$F$5:$F$1004,MATCH(27,Programação!$AE$5:$AE$1004,0))) -> Montar porta LE | D36: =IF($L$3<27,"",INDEX(Programação!$AG$5:$AG$1004,MATCH(27,Programação!$AE$5:$AE$1004,0))) -> Júnior | E36: =IF($L$3<27,"",INDEX(Programação!$O$5:$O$1004,MATCH(27,Programação!$AE$5:$AE$1004,0))) -> 46274 | F36: =IF($L$3<27,"",INDEX(Programação!$P$5:$P$1004,MATCH(27,Programação!$AE$5:$AE$1004,0))) -> 46275 | G36: =IF($A36="","",IF($H36<>"","Concluída",IF($F36<$C$3,"Atrasada",IF($F36=$C$3,"Fecha neste dia","Em execução")))) -> Em execução | H36: =IF($L$3<27,"",IF(INDEX(Programação!$AT$5:$AT$1004,MATCH(27,Programação!$AE$5:$AE$1004,0))="","",INDEX(Programação!$AT$5:$AT$1004,MATCH(27,Programação!$AE$5:$AE$1004,0)))) | I36: =IF($L$3<27,"",MATCH(27,Programação!$AE$5:$AE$1004,0)+4) -> 367
A37: =IF($L$3<28,"",INDEX(Programação!$D$5:$D$1004,MATCH(28,Programação!$AE$5:$AE$1004,0))) -> F-618 | B37: =IF($L$3<28,"",INDEX(Programação!$E$5:$E$1004,MATCH(28,Programação!$AE$5:$AE$1004,0))) -> Programação 09/09 | C37: =IF($L$3<28,"",INDEX(Programação!$F$5:$F$1004,MATCH(28,Programação!$AE$5:$AE$1004,0))) -> Instalar motor do vidro | D37: =IF($L$3<28,"",INDEX(Programação!$AG$5:$AG$1004,MATCH(28,Programação!$AE$5:$AE$1004,0))) -> Júnior | E37: =IF($L$3<28,"",INDEX(Programação!$O$5:$O$1004,MATCH(28,Programação!$AE$5:$AE$1004,0))) -> 46274 | F37: =IF($L$3<28,"",INDEX(Programação!$P$5:$P$1004,MATCH(28,Programação!$AE$5:$AE$1004,0))) -> 46276 | G37: =IF($A37="","",IF($H37<>"","Concluída",IF($F37<$C$3,"Atrasada",IF($F37=$C$3,"Fecha neste dia","Em execução")))) -> Em execução | H37: =IF($L$3<28,"",IF(INDEX(Programação!$AT$5:$AT$1004,MATCH(28,Programação!$AE$5:$AE$1004,0))="","",INDEX(Programação!$AT$5:$AT$1004,MATCH(28,Programação!$AE$5:$AE$1004,0)))) | I37: =IF($L$3<28,"",MATCH(28,Programação!$AE$5:$AE$1004,0)+4) -> 368
A38: =IF($L$3<29,"",INDEX(Programação!$D$5:$D$1004,MATCH(29,Programação!$AE$5:$AE$1004,0))) -> F-962 | B38: =IF($L$3<29,"",INDEX(Programação!$E$5:$E$1004,MATCH(29,Programação!$AE$5:$AE$1004,0))) -> Programação 09/09 | C38: =IF($L$3<29,"",INDEX(Programação!$F$5:$F$1004,MATCH(29,Programação!$AE$5:$AE$1004,0))) -> Fabricar tampa da caixa | D38: =IF($L$3<29,"",INDEX(Programação!$AG$5:$AG$1004,MATCH(29,Programação!$AE$5:$AE$1004,0))) -> Edilberto | E38: =IF($L$3<29,"",INDEX(Programação!$O$5:$O$1004,MATCH(29,Programação!$AE$5:$AE$1004,0))) -> 46274 | F38: =IF($L$3<29,"",INDEX(Programação!$P$5:$P$1004,MATCH(29,Programação!$AE$5:$AE$1004,0))) -> 46282 | G38: =IF($A38="","",IF($H38<>"","Concluída",IF($F38<$C$3,"Atrasada",IF($F38=$C$3,"Fecha neste dia","Em execução")))) -> Em execução | H38: =IF($L$3<29,"",IF(INDEX(Programação!$AT$5:$AT$1004,MATCH(29,Programação!$AE$5:$AE$1004,0))="","",INDEX(Programação!$AT$5:$AT$1004,MATCH(29,Programação!$AE$5:$AE$1004,0)))) | I38: =IF($L$3<29,"",MATCH(29,Programação!$AE$5:$AE$1004,0)+4) -> 369
A39: =IF($L$3<30,"",INDEX(Programação!$D$5:$D$1004,MATCH(30,Programação!$AE$5:$AE$1004,0))) -> F-434 | B39: =IF($L$3<30,"",INDEX(Programação!$E$5:$E$1004,MATCH(30,Programação!$AE$5:$AE$1004,0))) -> Programação 09/09 | C39: =IF($L$3<30,"",INDEX(Programação!$F$5:$F$1004,MATCH(30,Programação!$AE$5:$AE$1004,0))) -> Trocar pneus | D39: =IF($L$3<30,"",INDEX(Programação!$AG$5:$AG$1004,MATCH(30,Programação!$AE$5:$AE$1004,0))) -> Luiz Paulo | E39: =IF($L$3<30,"",INDEX(Programação!$O$5:$O$1004,MATCH(30,Programação!$AE$5:$AE$1004,0))) -> 46274 | F39: =IF($L$3<30,"",INDEX(Programação!$P$5:$P$1004,MATCH(30,Programação!$AE$5:$AE$1004,0))) -> 46275 | G39: =IF($A39="","",IF($H39<>"","Concluída",IF($F39<$C$3,"Atrasada",IF($F39=$C$3,"Fecha neste dia","Em execução")))) -> Em execução | H39: =IF($L$3<30,"",IF(INDEX(Programação!$AT$5:$AT$1004,MATCH(30,Programação!$AE$5:$AE$1004,0))="","",INDEX(Programação!$AT$5:$AT$1004,MATCH(30,Programação!$AE$5:$AE$1004,0)))) | I39: =IF($L$3<30,"",MATCH(30,Programação!$AE$5:$AE$1004,0)+4) -> 370
A40: =IF($L$3<31,"",INDEX(Programação!$D$5:$D$1004,MATCH(31,Programação!$AE$5:$AE$1004,0))) -> F-744 | B40: =IF($L$3<31,"",INDEX(Programação!$E$5:$E$1004,MATCH(31,Programação!$AE$5:$AE$1004,0))) -> Programação 09/09 | C40: =IF($L$3<31,"",INDEX(Programação!$F$5:$F$1004,MATCH(31,Programação!$AE$5:$AE$1004,0))) -> Trocar pneus | D40: =IF($L$3<31,"",INDEX(Programação!$AG$5:$AG$1004,MATCH(31,Programação!$AE$5:$AE$1004,0))) -> Luiz Paulo | E40: =IF($L$3<31,"",INDEX(Programação!$O$5:$O$1004,MATCH(31,Programação!$AE$5:$AE$1004,0))) -> 46274 | F40: =IF($L$3<31,"",INDEX(Programação!$P$5:$P$1004,MATCH(31,Programação!$AE$5:$AE$1004,0))) -> 46275 | G40: =IF($A40="","",IF($H40<>"","Concluída",IF($F40<$C$3,"Atrasada",IF($F40=$C$3,"Fecha neste dia","Em execução")))) -> Em execução | H40: =IF($L$3<31,"",IF(INDEX(Programação!$AT$5:$AT$1004,MATCH(31,Programação!$AE$5:$AE$1004,0))="","",INDEX(Programação!$AT$5:$AT$1004,MATCH(31,Programação!$AE$5:$AE$1004,0)))) | I40: =IF($L$3<31,"",MATCH(31,Programação!$AE$5:$AE$1004,0)+4) -> 371
...

Sheet Programação
A1: PROGRAMAÇÃO DE SERVIÇOS · MAKRO TRANSPORTES · SEMANA 37
A2: CALCULADO | C2: 1 · O QUE É O SERVIÇO | I2: 2 · QUEM FAZ — até três | L2: 3 · PROGRAMAR — semana, dia e quantos dias leva | O2: CALCULADO | Q2: 4 · SÓ QUANDO ACONTECER | V2: CALCULADO — não digite aqui | AM2: 5 · PRIORIDADE | AN2: CALCULADO — não digite aqui
A3: Linha | B3: Situação | C3: OS | D3: Frota | E3: Serviço | F3: Atividade | G3: Tipo | H3: Origem | I3: Executante 1 | J3: Executante 2 | K3: Executante 3 | L3: Semana | M3: Dia | N3: Dias prev. | O3: Início | P3: Prazo | Q3: Concluída em | R3: Marcar | S3: Semana orig. | T3: Motivo do atraso / da mudança | U3: Obs. | V3: Oficina | W3: Plano | X3: No prazo | Y3: No plano | Z3: Atraso | AA3: Reprog. | AB3: Concl. | AC3: Venc? | AD3: Fração | AE3: Ordem dia | AF3: Ordem atr. | AG3: Quem | AH3: Entra dia | AI3: Entra atr. | AJ3: Chave | AK3: Nº no serv. | AL3: Qtd no serv. | AM3: Prioridade | AN3: Cliente | AO3: Chave carteira | AP3: Ordem carteira | AQ3: É da frota | AR3: Ordem frota | AS3: Baixa da aba Hoje | AT3: Concluída efetiva
A5: =IF($F5="","",ROW()) -> 5 | B5: =IF($F5="",IF($D5="","","Falta a atividade"),IF($R5="Cancelada","Cancelada",IF($AB5=1,IF(N($Z5)>0,"Concluída com atraso","Concluída"),IF($R5="Em programação","Em programação",IF($O5="",IF($M5="","Na carteira","Falta a semana"),IF($AC5=1,"VENCIDA",IF($O5>Hoje!$L$1,"Programada",IF($P5>Hoje!$L$1,"Em execução","Fecha hoje")))))))) -> Concluída | C5: 021188 | D5: F-326 | E5: Calibração e troca de pneus | F5: Trocar pneus | G5: Corretiva | H5: Extra | I5: Airton | J5: Luiz Paulo | L5: 35 | M5: Qua | N5: 4 | O5: =IF(OR($L5="",$M5=""),"",(DATE(Semana!$J$3,1,4)-WEEKDAY(DATE(Semana!$J$3,1,4),3))+($L5-1)*7+MATCH($M5,Listas!$F$5:$F$11,0)-1) -> 46260 | P5: =IF(OR($F5="",$O5=""),"",$O5+MAX(0,ROUNDUP($AK5*MAX(1,IF($N5="",1,$N5))/MAX(1,$AL5),0)-1)) -> 46260 | Q5: 46260 | R5: Concluída | U5: Sistema: Pneus | V5: =IF($F5="","",IF(ISNUMBER(SEARCH("(externo)",$I5&$J5&$K5)),"Terceirizada","Interna")) -> Interna | W5: =IF($O5="","",IF($S5="",$O5,(DATE(Semana!$J$3,1,4)-WEEKDAY(DATE(Semana!$J$3,1,4),3))+($S5-1)*7+IF($M5="",0,MATCH($M5,Listas!$F$5:$F$11,0)-1))) -> 46260 | X5: =IF($F5="","",IF(OR($AT5="",$O5=""),0,IF($AT5<=$O5,1,0))) -> 1 | Y5: =IF($F5="","",IF(OR($AT5="",$W5=""),0,IF($AT5<=$W5,1,0))) -> 1 | Z5: =IF(OR($AT5="",$O5=""),"",MAX(0,$AT5-$O5)) -> 0 | AA5: =IF($F5="","",IF(AND($S5<>"",$L5<>"",$S5<>$L5),1,0)) -> 0 | AB5: =IF($F5="","",IF($R5="Cancelada",0,IF(OR($AT5<>"",$R5="Concluída"),1,0))) -> 1 | AC5: =IF($P5="",0,IF($P5<Hoje!$L$1,1,IF(AND($P5=Hoje!$L$1,Hoje!$L$2>Semana!$M$3),1,0))) -> 1 | AD5: =IF($F5="","",IF(COUNTA($I5:$K5)=0,0,1/COUNTA($I5:$K5))) -> 0.5 | AE5: =IF($AH5=0,"",SUM($AH$4:$AH5)) | AF5: =IF($AI5=0,"",SUM($AI$4:$AI5)) | AG5: =IF($F5="","",$I5&IF($J5="",""," · "&$J5)&IF($K5="",""," · "&$K5)) -> Airton · Luiz Paulo | AH5: =IF(AND($F5<>"",$O5<>"",$O5<=Hoje!$C$3,$P5>=Hoje!$C$3,$R5<>"Cancelada"),1,0) -> 0 | AI5: =IF(AND($F5<>"",$P5<>"",$P5<Hoje!$C$3,$AB5=0,$R5<>"Cancelada"),1,0) -> 0 | AJ5: =IF($F5="","",$D5&"|"&$E5&"|"&$L5) -> F-326|Calibração e troca de pneus|35 | AK5: =IF($AJ5="","",COUNTIF($AJ$4:$AJ5,$AJ5)) -> 1 | AL5: =IF($AJ5="","",COUNTIF($AJ$4:$AJ$1004,$AJ5)) -> 5 | AN5: =IF($D5="","",IFERROR(T(VLOOKUP($D5,Listas!$B$5:$H$120,7,0)),"")) | AO5: =IF(OR($F5="",$L5<>"",$R5="Cancelada",$AT5<>""),"",$AN5&"|"&$D5&"|"&IF($C5="","zzz",$C5)&"|"&TEXT(5,"0000")) | AP5: =IF($AO5="","",COUNTIF($AO$5:$AO$1004,"<"&$AO5)-(ROWS($AO$5:$AO$1004)-Hoje!$L$5)+1) | AQ5: =IF(AND($F5<>"",$D5=Frota!$C$3),1,0) -> 0 | AR5: =IF($AQ5=0,"",SUM($AQ$4:$AQ5)) | AS5: =IFERROR(INDEX(Hoje!$K$10:$K$29,MATCH(ROW(),Hoje!$J$10:$J$29,0)),"") | AT5: =IF($Q5<>"",$Q5,$AS5) -> 46260
A6: =IF($F6="","",ROW()) -> 6 | B6: =IF($F6="",IF($D6="","","Falta a atividade"),IF($R6="Cancelada","Cancelada",IF($AB6=1,IF(N($Z6)>0,"Concluída com atraso","Concluída"),IF($R6="Em programação","Em programação",IF($O6="",IF($M6="","Na carteira","Falta a semana"),IF($AC6=1,"VENCIDA",IF($O6>Hoje!$L$1,"Programada",IF($P6>Hoje!$L$1,"Em execução","Fecha hoje")))))))) -> Concluída | C6: 021188 | D6: F-326 | E6: Calibração e troca de pneus | F6: Substituir batentes dos eixos traseiros LE e LD gastos | G6: Corretiva | H6: Extra | I6: Júnior | L6: 35 | M6: Qua | N6: 4 | O6: =IF(OR($L6="",$M6=""),"",(DATE(Semana!$J$3,1,4)-WEEKDAY(DATE(Semana!$J$3,1,4),3))+($L6-1)*7+MATCH($M6,Listas!$F$5:$F$11,0)-1) -> 46260 | P6: =IF(OR($F6="",$O6=""),"",$O6+MAX(0,ROUNDUP($AK6*MAX(1,IF($N6="",1,$N6))/MAX(1,$AL6),0)-1)) -> 46261 | Q6: 46260 | R6: Concluída | U6: Sistema: Pneus · Serviço empresa especializada · peça 20390836 (4 unidades) | V6: =IF($F6="","",IF(ISNUMBER(SEARCH("(externo)",$I6&$J6&$K6)),"Terceirizada","Interna")) -> Interna | W6: =IF($O6="","",IF($S6="",$O6,(DATE(Semana!$J$3,1,4)-WEEKDAY(DATE(Semana!$J$3,1,4),3))+($S6-1)*7+IF($M6="",0,MATCH($M6,Listas!$F$5:$F$11,0)-1))) -> 46260 | X6: =IF($F6="","",IF(OR($AT6="",$O6=""),0,IF($AT6<=$O6,1,0))) -> 1 | Y6: =IF($F6="","",IF(OR($AT6="",$W6=""),0,IF($AT6<=$W6,1,0))) -> 1 | Z6: =IF(OR($AT6="",$O6=""),"",MAX(0,$AT6-$O6)) -> 0 | AA6: =IF($F6="","",IF(AND($S6<>"",$L6<>"",$S6<>$L6),1,0)) -> 0 | AB6: =IF($F6="","",IF($R6="Cancelada",0,IF(OR($AT6<>"",$R6="Concluída"),1,0))) -> 1 | AC6: =IF($P6="",0,IF($P6<Hoje!$L$1,1,IF(AND($P6=Hoje!$L$1,Hoje!$L$2>Semana!$M$3),1,0))) -> 1 | AD6: =IF($F6="","",IF(COUNTA($I6:$K6)=0,0,1/COUNTA($I6:$K6))) -> 1 | AE6: =IF($AH6=0,"",SUM($AH$4:$AH6)) | AF6: =IF($AI6=0,"",SUM($AI$4:$AI6)) | AG6: =IF($F6="","",$I6&IF($J6="",""," · "&$J6)&IF($K6="",""," · "&$K6)) -> Júnior | AH6: =IF(AND($F6<>"",$O6<>"",$O6<=Hoje!$C$3,$P6>=Hoje!$C$3,$R6<>"Cancelada"),1,0) -> 0 | AI6: =IF(AND($F6<>"",$P6<>"",$P6<Hoje!$C$3,$AB6=0,$R6<>"Cancelada"),1,0) -> 0 | AJ6: =IF($F6="","",$D6&"|"&$E6&"|"&$L6) -> F-326|Calibração e troca de pneus|35 | AK6: =IF($AJ6="","",COUNTIF($AJ$4:$AJ6,$AJ6)) -> 2 | AL6: =IF($AJ6="","",COUNTIF($AJ$4:$AJ$1004,$AJ6)) -> 5 | AN6: =IF($D6="","",IFERROR(T(VLOOKUP($D6,Listas!$B$5:$H$120,7,0)),"")) | AO6: =IF(OR($F6="",$L6<>"",$R6="Cancelada",$AT6<>""),"",$AN6&"|"&$D6&"|"&IF($C6="","zzz",$C6)&"|"&TEXT(6,"0000")) | AP6: =IF($AO6="","",COUNTIF($AO$5:$AO$1004,"<"&$AO6)-(ROWS($AO$5:$AO$1004)-Hoje!$L$5)+1) | AQ6: =IF(AND($F6<>"",$D6=Frota!$C$3),1,0) -> 0 | AR6: =IF($AQ6=0,"",SUM($AQ$4:$AQ6)) | AS6: =IFERROR(INDEX(Hoje!$K$10:$K$29,MATCH(ROW(),Hoje!$J$10:$J$29,0)),"") | AT6: =IF($Q6<>"",$Q6,$AS6) -> 46260
A7: =IF($F7="","",ROW()) -> 7 | B7: =IF($F7="",IF($D7="","","Falta a atividade"),IF($R7="Cancelada","Cancelada",IF($AB7=1,IF(N($Z7)>0,"Concluída com atraso","Concluída"),IF($R7="Em programação","Em programação",IF($O7="",IF($M7="","Na carteira","Falta a semana"),IF($AC7=1,"VENCIDA",IF($O7>Hoje!$L$1,"Programada",IF($P7>Hoje!$L$1,"Em execução","Fecha hoje")))))))) -> Concluída | C7: 021188 | D7: F-326 | E7: Calibração e troca de pneus | F7: Soldar base do paralama dianteiro LD avariada | G7: Corretiva | H7: Extra | I7: Júnior | L7: 35 | M7: Qua | N7: 4 | O7: =IF(OR($L7="",$M7=""),"",(DATE(Semana!$J$3,1,4)-WEEKDAY(DATE(Semana!$J$3,1,4),3))+($L7-1)*7+MATCH($M7,Listas!$F$5:$F$11,0)-1) -> 46260 | P7: =IF(OR($F7="",$O7=""),"",$O7+MAX(0,ROUNDUP($AK7*MAX(1,IF($N7="",1,$N7))/MAX(1,$AL7),0)-1)) -> 46262 | Q7: 46260 | R7: Concluída | U7: Sistema: Pneus · 20453900 | V7: =IF($F7="","",IF(ISNUMBER(SEARCH("(externo)",$I7&$J7&$K7)),"Terceirizada","Interna")) -> Interna | W7: =IF($O7="","",IF($S7="",$O7,(DATE(Semana!$J$3,1,4)-WEEKDAY(DATE(Semana!$J$3,1,4),3))+($S7-1)*7+IF($M7="",0,MATCH($M7,Listas!$F$5:$F$11,0)-1))) -> 46260 | X7: =IF($F7="","",IF(OR($AT7="",$O7=""),0,IF($AT7<=$O7,1,0))) -> 1 | Y7: =IF($F7="","",IF(OR($AT7="",$W7=""),0,IF($AT7<=$W7,1,0))) -> 1 | Z7: =IF(OR($AT7="",$O7=""),"",MAX(0,$AT7-$O7)) -> 0 | AA7: =IF($F7="","",IF(AND($S7<>"",$L7<>"",$S7<>$L7),1,0)) -> 0 | AB7: =IF($F7="","",IF($R7="Cancelada",0,IF(OR($AT7<>"",$R7="Concluída"),1,0))) -> 1 | AC7: =IF($P7="",0,IF($P7<Hoje!$L$1,1,IF(AND($P7=Hoje!$L$1,Hoje!$L$2>Semana!$M$3),1,0))) -> 1 | AD7: =IF($F7="","",IF(COUNTA($I7:$K7)=0,0,1/COUNTA($I7:$K7))) -> 1 | AE7: =IF($AH7=0,"",SUM($AH$4:$AH7)) | AF7: =IF($AI7=0,"",SUM($AI$4:$AI7)) | AG7: =IF($F7="","",$I7&IF($J7="",""," · "&$J7)&IF($K7="",""," · "&$K7)) -> Júnior | AH7: =IF(AND($F7<>"",$O7<>"",$O7<=Hoje!$C$3,$P7>=Hoje!$C$3,$R7<>"Cancelada"),1,0) -> 0 | AI7: =IF(AND($F7<>"",$P7<>"",$P7<Hoje!$C$3,$AB7=0,$R7<>"Cancelada"),1,0) -> 0 | AJ7: =IF($F7="","",$D7&"|"&$E7&"|"&$L7) -> F-326|Calibração e troca de pneus|35 | AK7: =IF($AJ7="","",COUNTIF($AJ$4:$AJ7,$AJ7)) -> 3 | AL7: =IF($AJ7="","",COUNTIF($AJ$4:$AJ$1004,$AJ7)) -> 5 | AN7: =IF($D7="","",IFERROR(T(VLOOKUP($D7,Listas!$B$5:$H$120,7,0)),"")) | AO7: =IF(OR($F7="",$L7<>"",$R7="Cancelada",$AT7<>""),"",$AN7&"|"&$D7&"|"&IF($C7="","zzz",$C7)&"|"&TEXT(7,"0000")) | AP7: =IF($AO7="","",COUNTIF($AO$5:$AO$1004,"<"&$AO7)-(ROWS($AO$5:$AO$1004)-Hoje!$L$5)+1) | AQ7: =IF(AND($F7<>"",$D7=Frota!$C$3),1,0) -> 0 | AR7: =IF($AQ7=0,"",SUM($AQ$4:$AQ7)) | AS7: =IFERROR(INDEX(Hoje!$K$10:$K$29,MATCH(ROW(),Hoje!$J$10:$J$29,0)),"") | AT7: =IF($Q7<>"",$Q7,$AS7) -> 46260
A8: =IF($F8="","",ROW()) -> 8 | B8: =IF($F8="",IF($D8="","","Falta a atividade"),IF($R8="Cancelada","Cancelada",IF($AB8=1,IF(N($Z8)>0,"Concluída com atraso","Concluída"),IF($R8="Em programação","Em programação",IF($O8="",IF($M8="","Na carteira","Falta a semana"),IF($AC8=1,"VENCIDA",IF($O8>Hoje!$L$1,"Programada",IF($P8>Hoje!$L$1,"Em execução","Fecha hoje")))))))) -> Concluída | C8: 021188 | D8: F-326 | E8: Calibração e troca de pneus | F8: Substituir acabamento do retrovisor inferior LD | G8: Corretiva | H8: Extra | I8: Júnior | L8: 35 | M8: Qua | N8: 4 | O8: =IF(OR($L8="",$M8=""),"",(DATE(Semana!$J$3,1,4)-WEEKDAY(DATE(Semana!$J$3,1,4),3))+($L8-1)*7+MATCH($M8,Listas!$F$5:$F$11,0)-1) -> 46260 | P8: =IF(OR($F8="",$O8=""),"",$O8+MAX(0,ROUNDUP($AK8*MAX(1,IF($N8="",1,$N8))/MAX(1,$AL8),0)-1)) -> 46263 | Q8: 46260 | R8: Concluída | U8: Sistema: Pneus · item em aplicação direta ou realizar pedido 21169971 | V8: =IF($F8="","",IF(ISNUMBER(SEARCH("(externo)",$I8&$J8&$K8)),"Terceirizada","Interna")) -> Interna | W8: =IF($O8="","",IF($S8="",$O8,(DATE(Semana!$J$3,1,4)-WEEKDAY(DATE(Semana!$J$3,1,4),3))+($S8-1)*7+IF($M8="",0,MATCH($M8,Listas!$F$5:$F$11,0)-1))) -> 46260 | X8: =IF($F8="","",IF(OR($AT8="",$O8=""),0,IF($AT8<=$O8,1,0))) -> 1 | Y8: =IF($F8="","",IF(OR($AT8="",$W8=""),0,IF($AT8<=$W8,1,0))) -> 1 | Z8: =IF(OR($AT8="",$O8=""),"",MAX(0,$AT8-$O8)) -> 0 | AA8: =IF($F8="","",IF(AND($S8<>"",$L8<>"",$S8<>$L8),1,0)) -> 0 | AB8: =IF($F8="","",IF($R8="Cancelada",0,IF(OR($AT8<>"",$R8="Concluída"),1,0))) -> 1 | AC8: =IF($P8="",0,IF($P8<Hoje!$L$1,1,IF(AND($P8=Hoje!$L$1,Hoje!$L$2>Semana!$M$3),1,0))) -> 1 | AD8: =IF($F8="","",IF(COUNTA($I8:$K8)=0,0,1/COUNTA($I8:$K8))) -> 1 | AE8: =IF($AH8=0,"",SUM($AH$4:$AH8)) | AF8: =IF($AI8=0,"",SUM($AI$4:$AI8)) | AG8: =IF($F8="","",$I8&IF($J8="",""," · "&$J8)&IF($K8="",""," · "&$K8)) -> Júnior | AH8: =IF(AND($F8<>"",$O8<>"",$O8<=Hoje!$C$3,$P8>=Hoje!$C$3,$R8<>"Cancelada"),1,0) -> 0 | AI8: =IF(AND($F8<>"",$P8<>"",$P8<Hoje!$C$3,$AB8=0,$R8<>"Cancelada"),1,0) -> 0 | AJ8: =IF($F8="","",$D8&"|"&$E8&"|"&$L8) -> F-326|Calibração e troca de pneus|35 | AK8: =IF($AJ8="","",COUNTIF($AJ$4:$AJ8,$AJ8)) -> 4 | AL8: =IF($AJ8="","",COUNTIF($AJ$4:$AJ$1004,$AJ8)) -> 5 | AN8: =IF($D8="","",IFERROR(T(VLOOKUP($D8,Listas!$B$5:$H$120,7,0)),"")) | AO8: =IF(OR($F8="",$L8<>"",$R8="Cancelada",$AT8<>""),"",$AN8&"|"&$D8&"|"&IF($C8="","zzz",$C8)&"|"&TEXT(8,"0000")) | AP8: =IF($AO8="","",COUNTIF($AO$5:$AO$1004,"<"&$AO8)-(ROWS($AO$5:$AO$1004)-Hoje!$L$5)+1) | AQ8: =IF(AND($F8<>"",$D8=Frota!$C$3),1,0) -> 0 | AR8: =IF($AQ8=0,"",SUM($AQ$4:$AQ8)) | AS8: =IFERROR(INDEX(Hoje!$K$10:$K$29,MATCH(ROW(),Hoje!$J$10:$J$29,0)),"") | AT8: =IF($Q8<>"",$Q8,$AS8) -> 46260
A9: =IF($F9="","",ROW()) -> 9 | B9: =IF($F9="",IF($D9="","","Falta a atividade"),IF($R9="Cancelada","Cancelada",IF($AB9=1,IF(N($Z9)>0,"Concluída com atraso","Concluída"),IF($R9="Em programação","Em programação",IF($O9="",IF($M9="","Na carteira","Falta a semana"),IF($AC9=1,"VENCIDA",IF($O9>Hoje!$L$1,"Programada",IF($P9>Hoje!$L$1,"Em execução","Fecha hoje")))))))) -> Concluída | C9: 021188 | D9: F-326 | E9: Calibração e troca de pneus | F9: CARCAÇA INTERNA DO FAROL | G9: Corretiva | H9: Extra | I9: Júnior | L9: 35 | M9: Qua | N9: 4 | O9: =IF(OR($L9="",$M9=""),"",(DATE(Semana!$J$3,1,4)-WEEKDAY(DATE(Semana!$J$3,1,4),3))+($L9-1)*7+MATCH($M9,Listas!$F$5:$F$11,0)-1) -> 46260 | P9: =IF(OR($F9="",$O9=""),"",$O9+MAX(0,ROUNDUP($AK9*MAX(1,IF($N9="",1,$N9))/MAX(1,$AL9),0)-1)) -> 46263 | Q9: 46260 | R9: Concluída | U9: Sistema: Pneus · 20453627 | V9: =IF($F9="","",IF(ISNUMBER(SEARCH("(externo)",$I9&$J9&$K9)),"Terceirizada","Interna")) -> Interna | W9: =IF($O9="","",IF($S9="",$O9,(DATE(Semana!$J$3,1,4)-WEEKDAY(DATE(Semana!$J$3,1,4),3))+($S9-1)*7+IF($M9="",0,MATCH($M9,Listas!$F$5:$F$11,0)-1))) -> 46260 | X9: =IF($F9="","",IF(OR($AT9="",$O9=""),0,IF($AT9<=$O9,1,0))) -> 1 | Y9: =IF($F9="","",IF(OR($AT9="",$W9=""),0,IF($AT9<=$W9,1,0))) -> 1 | Z9: =IF(OR($AT9="",$O9=""),"",MAX(0,$AT9-$O9)) -> 0 | AA9: =IF($F9="","",IF(AND($S9<>"",$L9<>"",$S9<>$L9),1,0)) -> 0 | AB9: =IF($F9="","",IF($R9="Cancelada",0,IF(OR($AT9<>"",$R9="Concluída"),1,0))) -> 1 | AC9: =IF($P9="",0,IF($P9<Hoje!$L$1,1,IF(AND($P9=Hoje!$L$1,Hoje!$L$2>Semana!$M$3),1,0))) -> 1 | AD9: =IF($F9="","",IF(COUNTA($I9:$K9)=0,0,1/COUNTA($I9:$K9))) -> 1 | AE9: =IF($AH9=0,"",SUM($AH$4:$AH9)) | AF9: =IF($AI9=0,"",SUM($AI$4:$AI9)) | AG9: =IF($F9="","",$I9&IF($J9="",""," · "&$J9)&IF($K9="",""," · "&$K9)) -> Júnior | AH9: =IF(AND($F9<>"",$O9<>"",$O9<=Hoje!$C$3,$P9>=Hoje!$C$3,$R9<>"Cancelada"),1,0) -> 0 | AI9: =IF(AND($F9<>"",$P9<>"",$P9<Hoje!$C$3,$AB9=0,$R9<>"Cancelada"),1,0) -> 0 | AJ9: =IF($F9="","",$D9&"|"&$E9&"|"&$L9) -> F-326|Calibração e troca de pneus|35 | AK9: =IF($AJ9="","",COUNTIF($AJ$4:$AJ9,$AJ9)) -> 5 | AL9: =IF($AJ9="","",COUNTIF($AJ$4:$AJ$1004,$AJ9)) -> 5 | AN9: =IF($D9="","",IFERROR(T(VLOOKUP($D9,Listas!$B$5:$H$120,7,0)),"")) | AO9: =IF(OR($F9="",$L9<>"",$R9="Cancelada",$AT9<>""),"",$AN9&"|"&$D9&"|"&IF($C9="","zzz",$C9)&"|"&TEXT(9,"0000")) | AP9: =IF($AO9="","",COUNTIF($AO$5:$AO$1004,"<"&$AO9)-(ROWS($AO$5:$AO$1004)-Hoje!$L$5)+1) | AQ9: =IF(AND($F9<>"",$D9=Frota!$C$3),1,0) -> 0 | AR9: =IF($AQ9=0,"",SUM($AQ$4:$AQ9)) | AS9: =IFERROR(INDEX(Hoje!$K$10:$K$29,MATCH(ROW(),Hoje!$J$10:$J$29,0)),"") | AT9: =IF($Q9<>"",$Q9,$AS9) -> 46260
A10: =IF($F10="","",ROW()) -> 10 | B10: =IF($F10="",IF($D10="","","Falta a atividade"),IF($R10="Cancelada","Cancelada",IF($AB10=1,IF(N($Z10)>0,"Concluída com atraso","Concluída"),IF($R10="Em programação","Em programação",IF($O10="",IF($M10="","Na carteira","Falta a semana"),IF($AC10=1,"VENCIDA",IF($O10>Hoje!$L$1,"Programada",IF($P10>Hoje!$L$1,"Em execução","Fecha hoje")))))))) -> Concluída | C10: 019784 | D10: F-327 | E10: Montar adesivos e baixa de carteira | F10: Realizar lavagem e corrigir vazamento na bomba de direção | G10: Corretiva | H10: Programada | I10: Júnior | L10: 35 | M10: Qua | N10: 3 | O10: =IF(OR($L10="",$M10=""),"",(DATE(Semana!$J$3,1,4)-WEEKDAY(DATE(Semana!$J$3,1,4),3))+($L10-1)*7+MATCH($M10,Listas!$F$5:$F$11,0)-1) -> 46260 | P10: =IF(OR($F10="",$O10=""),"",$O10+MAX(0,ROUNDUP($AK10*MAX(1,IF($N10="",1,$N10))/MAX(1,$AL10),0)-1)) -> 46260 | Q10: 46260 | R10: Concluída | U10: serviço interno Matriz | V10: =IF($F10="","",IF(ISNUMBER(SEARCH("(externo)",$I10&$J10&$K10)),"Terceirizada","Interna")) -> Interna | W10: =IF($O10="","",IF($S10="",$O10,(DATE(Semana!$J$3,1,4)-WEEKDAY(DATE(Semana!$J$3,1,4),3))+($S10-1)*7+IF($M10="",0,MATCH($M10,Listas!$F$5:$F$11,0)-1))) -> 46260 | X10: =IF($F10="","",IF(OR($AT10="",$O10=""),0,IF($AT10<=$O10,1,0))) -> 1 | Y10: =IF($F10="","",IF(OR($AT10="",$W10=""),0,IF($AT10<=$W10,1,0))) -> 1 | Z10: =IF(OR($AT10="",$O10=""),"",MAX(0,$AT10-$O10)) -> 0 | AA10: =IF($F10="","",IF(AND($S10<>"",$L10<>"",$S10<>$L10),1,0)) -> 0 | AB10: =IF($F10="","",IF($R10="Cancelada",0,IF(OR($AT10<>"",$R10="Concluída"),1,0))) -> 1 | AC10: =IF($P10="",0,IF($P10<Hoje!$L$1,1,IF(AND($P10=Hoje!$L$1,Hoje!$L$2>Semana!$M$3),1,0))) -> 1 | AD10: =IF($F10="","",IF(COUNTA($I10:$K10)=0,0,1/COUNTA($I10:$K10))) -> 1 | AE10: =IF($AH10=0,"",SUM($AH$4:$AH10)) | AF10: =IF($AI10=0,"",SUM($AI$4:$AI10)) | AG10: =IF($F10="","",$I10&IF($J10="",""," · "&$J10)&IF($K10="",""," · "&$K10)) -> Júnior | AH10: =IF(AND($F10<>"",$O10<>"",$O10<=Hoje!$C$3,$P10>=Hoje!$C$3,$R10<>"Cancelada"),1,0) -> 0 | AI10: =IF(AND($F10<>"",$P10<>"",$P10<Hoje!$C$3,$AB10=0,$R10<>"Cancelada"),1,0) -> 0 | AJ10: =IF($F10="","",$D10&"|"&$E10&"|"&$L10) -> F-327|Montar adesivos e baixa de carteira|35 | AK10: =IF($AJ10="","",COUNTIF($AJ$4:$AJ10,$AJ10)) -> 1 | AL10: =IF($AJ10="","",COUNTIF($AJ$4:$AJ$1004,$AJ10)) -> 4 | AN10: =IF($D10="","",IFERROR(T(VLOOKUP($D10,Listas!$B$5:$H$120,7,0)),"")) | AO10: =IF(OR($F10="",$L10<>"",$R10="Cancelada",$AT10<>""),"",$AN10&"|"&$D10&"|"&IF($C10="","zzz",$C10)&"|"&TEXT(10,"0000")) | AP10: =IF($AO10="","",COUNTIF($AO$5:$AO$1004,"<"&$AO10)-(ROWS($AO$5:$AO$1004)-Hoje!$L$5)+1) | AQ10: =IF(AND($F10<>"",$D10=Frota!$C$3),1,0) -> 0 | AR10: =IF($AQ10=0,"",SUM($AQ$4:$AQ10)) | AS10: =IFERROR(INDEX(Hoje!$K$10:$K$29,MATCH(ROW(),Hoje!$J$10:$J$29,0)),"") | AT10: =IF($Q10<>"",$Q10,$AS10) -> 46260
A11: =IF($F11="","",ROW()) -> 11 | B11: =IF($F11="",IF($D11="","","Falta a atividade"),IF($R11="Cancelada","Cancelada",IF($AB11=1,IF(N($Z11)>0,"Concluída com atraso","Concluída"),IF($R11="Em programação","Em programação",IF($O11="",IF($M11="","Na carteira","Falta a semana"),IF($AC11=1,"VENCIDA",IF($O11>Hoje!$L$1,"Programada",IF($P11>Hoje!$L$1,"Em execução","Fecha hoje")))))))) -> Concluída | C11: 019784 | D11: F-327 | E11: Montar adesivos e baixa de carteira | F11: Regular travamento das portas, motorista relata que as mesmas estão abrindo em movimento | G11: Corretiva | H11: Programada | I11: Júnior | L11: 35 | M11: Qua | N11: 3 | O11: =IF(OR($L11="",$M11=""),"",(DATE(Semana!$J$3,1,4)-WEEKDAY(DATE(Semana!$J$3,1,4),3))+($L11-1)*7+MATCH($M11,Listas!$F$5:$F$11,0)-1) -> 46260 | P11: =IF(OR($F11="",$O11=""),"",$O11+MAX(0,ROUNDUP($AK11*MAX(1,IF($N11="",1,$N11))/MAX(1,$AL11),0)-1)) -> 46261 | Q11: 46260 | R11: Concluída | U11: serviço interno Matriz | V11: =IF($F11="","",IF(ISNUMBER(SEARCH("(externo)",$I11&$J11&$K11)),"Terceirizada","Interna")) -> Interna | W11: =IF($O11="","",IF($S11="",$O11,(DATE(Semana!$J$3,1,4)-WEEKDAY(DATE(Semana!$J$3,1,4),3))+($S11-1)*7+IF($M11="",0,MATCH($M11,Listas!$F$5:$F$11,0)-1))) -> 46260 | X11: =IF($F11="","",IF(OR($AT11="",$O11=""),0,IF($AT11<=$O11,1,0))) -> 1 | Y11: =IF($F11="","",IF(OR($AT11="",$W11=""),0,IF($AT11<=$W11,1,0))) -> 1 | Z11: =IF(OR($AT11="",$O11=""),"",MAX(0,$AT11-$O11)) -> 0 | AA11: =IF($F11="","",IF(AND($S11<>"",$L11<>"",$S11<>$L11),1,0)) -> 0 | AB11: =IF($F11="","",IF($R11="Cancelada",0,IF(OR($AT11<>"",$R11="Concluída"),1,0))) -> 1 | AC11: =IF($P11="",0,IF($P11<Hoje!$L$1,1,IF(AND($P11=Hoje!$L$1,Hoje!$L$2>Semana!$M$3),1,0))) -> 1 | AD11: =IF($F11="","",IF(COUNTA($I11:$K11)=0,0,1/COUNTA($I11:$K11))) -> 1 | AE11: =IF($AH11=0,"",SUM($AH$4:$AH11)) | AF11: =IF($AI11=0,"",SUM($AI$4:$AI11)) | AG11: =IF($F11="","",$I11&IF($J11="",""," · "&$J11)&IF($K11="",""," · "&$K11)) -> Júnior | AH11: =IF(AND($F11<>"",$O11<>"",$O11<=Hoje!$C$3,$P11>=Hoje!$C$3,$R11<>"Cancelada"),1,0) -> 0 | AI11: =IF(AND($F11<>"",$P11<>"",$P11<Hoje!$C$3,$AB11=0,$R11<>"Cancelada"),1,0) -> 0 | AJ11: =IF($F11="","",$D11&"|"&$E11&"|"&$L11) -> F-327|Montar adesivos e baixa de carteira|35 | AK11: =IF($AJ11="","",COUNTIF($AJ$4:$AJ11,$AJ11)) -> 2 | AL11: =IF($AJ11="","",COUNTIF($AJ$4:$AJ$1004,$AJ11)) -> 4 | AN11: =IF($D11="","",IFERROR(T(VLOOKUP($D11,Listas!$B$5:$H$120,7,0)),"")) | AO11: =IF(OR($F11="",$L11<>"",$R11="Cancelada",$AT11<>""),"",$AN11&"|"&$D11&"|"&IF($C11="","zzz",$C11)&"|"&TEXT(11,"0000")) | AP11: =IF($AO11="","",COUNTIF($AO$5:$AO$1004,"<"&$AO11)-(ROWS($AO$5:$AO$1004)-Hoje!$L$5)+1) | AQ11: =IF(AND($F11<>"",$D11=Frota!$C$3),1,0) -> 0 | AR11: =IF($AQ11=0,"",SUM($AQ$4:$AQ11)) | AS11: =IFERROR(INDEX(Hoje!$K$10:$K$29,MATCH(ROW(),Hoje!$J$10:$J$29,0)),"") | AT11: =IF($Q11<>"",$Q11,$AS11) -> 46260
